AssertionError: Failure during projection 50: NLOPT failure Failure during projection 4: NLOPT failure Failure during projection 55: NLOPT failure Failure during projection 41: NLOPT failure Failure during projection 7: NLOPT failure Failure during projection 61: NLOPT failure Failure during projection 12: NLOPT failure Failure during projection 31: NLOPT failure
The above exception was the direct cause of the following exception:
Traceback (most recent call last):
  File "/home/luyao/amortized_vi_trpl/GMM/GMM_model.py", line 162, in <module>
    train_model(model, target, n_epochs, batch_size, n_context, n_components, eps, optimizer)
  File "/home/luyao/amortized_vi_trpl/GMM/GMM_model.py", line 95, in train_model
    mean_proj_j, cov_proj_j = KLProjection.apply((mean_pred_j, cov_pred_j), (mean_old_j, cov_old_j), eps)
  File "/home/luyao/amortized_vi_trpl/Gaussian/kl_projection.py", line 33, in forward
    proj_mean, proj_cov = p_op.forward(epss, betas, old_mean, old_cov, mean, cov)
SystemError: <built-in method forward of PyCapsule object at 0x7fd0a1b87b10> returned a result with an error set