AssertionError: Failure during projection 18: NLOPT failure Failure during projection 51: NLOPT failure Failure during projection 28: NLOPT failure Failure during projection 57: NLOPT failure Failure during projection 44: NLOPT failure Failure during projection 29: NLOPT failure
The above exception was the direct cause of the following exception:
Traceback (most recent call last):
  File "/home/luyao/amortized_vi_trpl/GMM/GMM_model.py", line 168, in <module>
    train_model(model, target, n_epochs, batch_size, n_context, n_components, eps, beta, optimizer)
  File "/home/luyao/amortized_vi_trpl/GMM/GMM_model.py", line 94, in train_model
    eps, beta)
  File "/home/luyao/amortized_vi_trpl/Gaussian/kl_projection.py", line 32, in forward
    proj_mean, proj_cov = p_op.forward(epss, betas, old_mean, old_cov, mean, cov)
SystemError: <built-in method forward of PyCapsule object at 0x7f4dc6fb92a0> returned a result with an error set