AssertionError: Failure during projection 19: NLOPT failure
The above exception was the direct cause of the following exception:
Traceback (most recent call last):
  File "/home/luyao/amortized_vi_trpl/GMM/GMM_model.py", line 186, in <module>
    train_model(model, target, n_epochs, batch_size, n_context, n_components, eps, beta, optimizer, device)
  File "/home/luyao/amortized_vi_trpl/GMM/GMM_model.py", line 113, in train_model
    eps, beta)
  File "/home/luyao/amortized_vi_trpl/Gaussian/kl_projection.py", line 32, in forward
    proj_mean, proj_cov = p_op.forward(epss, betas, old_mean, old_cov, mean, cov)
SystemError: <built-in method forward of PyCapsule object at 0x7f2d2c323720> returned a result with an error set